Workbook

Sheet Model
A1: Total cost for 2-4 | B1: =VLOOKUP(RANDBETWEEN(1,1000),'cost sheets'!$G$2:$M$1002,7,FALSE) -> 60 | C1: Fixed cost whole year | D1: ='cost sheets'!D1 -> 900
A2: total cost for 4-6 | B2: =VLOOKUP(RANDBETWEEN(1,1000),'cost sheets'!N2:T1002,7,FALSE) -> 0
A3: total cost 6-8 | B3: =VLOOKUP(RANDBETWEEN(1,1000),'cost sheets'!U2:AA1002,7,FALSE) -> 100
A4: total cost 8-12 | B4: =VLOOKUP(RANDBETWEEN(1,1000),'cost sheets'!AB2:AH1002,7,FALSE) -> 0
A5: total cost for 12+ | B5: =VLOOKUP(RANDBETWEEN(1,1000),'cost sheets'!AI2:AO1002,7,FALSE) -> 0
A6: total cost for winter | B6: =SUM(B1:B5) -> 160
A7: 2 | B7: 580 | H7: Count | I7: =COUNT(B6:B1005) -> 1000
A8: 3 | B8: 680 | H8: Minimum | I8: =MIN(B6:B1005) -> 0
A9: 4 | B9: 360 | H9: Maximum | I9: =MAX(B6:B1005) -> 1950
A10: 5 | B10: 1070 | H10: Average | I10: =AVERAGE(B6:B1005) -> 647.36
A11: 6 | B11: 500 | H11: Standard Deviation | I11: =_xlfn.STDEV.S(B6:B1005) -> 264.04536
A12: 7 | B12: 520 | H12: number of times doing verialbe cost is cheaper | I12: =COUNTIF(B6:B1005,"<900") -> 834
A13: 8 | B13: 840 | H13: percenate of times doing fix is cheaper | I13: =I12/I7 -> 0.834
A14: 9 | B14: 580
A15: 10 | B15: 450
A16: 11 | B16: 720
A17: 12 | B17: 570
A18: 13 | B18: 870
A19: 14 | B19: 750
A20: 15 | B20: 280
A21: 16 | B21: 950
A22: 17 | B22: 950
A23: 18 | B23: 1070
A24: 19 | B24: 1260
A25: 20 | B25: 220
... A1005: 1000 | B1005: 720
B1006: 570

Sheet cost sheets
A1: fixed cost | B1: 180 | C1: Fixed cost whole year | D1: =B1*5 -> 900 | G1: Simulation
A2: 2-4 | B2: 60 | H2: Nov 2-4 in | I2: DEC 2-4 IN | J2: JAN 2-4 IN | K2: FEB 2-4 IN | L2: MAR 2-4 IN | M2: Total 2-4 IN cost | O2: Nov4-6 IN | P2: Dec 4-6 IN | Q2: JAN 4-6 IN | R2: FEB 4-6 IN | S2: Mar 4-6 IN | T2: Total 4-6 IN cost | V2: Nove 6-8 | W2: Dec 6-8 | X2: Jan 6-8 | Y2: Feb 6-8 | Z2: Mar 6-8 | AA2: Total 6-8 cost | AC2: Nov 8-12 | AD2: Dec 8-12 | AE2: Jan 8-12 | AF2: Feb 8-12 | AG2: Mar 8-12 | AH2: Total cost 8-12 | AJ2: Nov 12+ | AK2: Dec 12+ | AL2: Jan 12+ | AM2: Feb 12+ | AN2: Mar 12+ | AO2: Total cost 12 +
A3: 4-6 | B3: 80 | G3: 1 | H3: =VLOOKUP(RAND(),A9:C14,3,TRUE) -> 0 | I3: =VLOOKUP(RAND(),A15:C21,3,TRUE) -> 0 | J3: =VLOOKUP(RAND(),A22:C28,3,TRUE) -> 1 | K3: =VLOOKUP(RAND(),A29:C34,3,TRUE) -> 4 | L3: =VLOOKUP(RAND(),A35:C40,3,TRUE) -> 2 | M3: =SUM(H3:L3)*B2 -> 420 | N3: 1 | O3: =VLOOKUP(RAND(),A42:C46,3,TRUE) -> 1 | P3: =VLOOKUP(RAND(),A47:C50,3,TRUE) -> 1 | Q3: =VLOOKUP(RAND(),A51:C55,3,TRUE) -> 1 | R3: =VLOOKUP(RAND(),A56:C60,3,TRUE) -> 0 | S3: =VLOOKUP(RAND(),A62:C64,3,TRUE) -> 0 | T3: =SUM(O3:S3)*B3 -> 240 | U3: 1 | V3: =VLOOKUP(RAND(),A66:C68,3,TRUE) -> 0 | W3: =VLOOKUP(RAND(),A70:C73,3,TRUE) -> 0 | X3: =VLOOKUP(RAND(),A74:C76,3,TRUE) -> 0 | Y3: =VLOOKUP(RAND(),A77:C80,3,TRUE) -> 0 | Z3: =VLOOKUP(RAND(),A81:C83,3,TRUE) -> 0 | AA3: =SUM(V3:Z3)*B4 -> 0 | AB3: 1 | AC3: =VLOOKUP(RAND(),A85:C88,3,TRUE) -> 0 | AD3: =VLOOKUP(RAND(),A89:C91,3,TRUE) -> 0 | AE3: =VLOOKUP(RAND(),A92:C94,3,TRUE) -> 0 | AF3: =VLOOKUP(RAND(),A95:C97,3,TRUE) -> 0 | AG3: =VLOOKUP(RAND(),A98:C101,3,TRUE) -> 0 | AH3: =SUM(AC3:AG3)*B5 -> 0 | AI3: 1 | AJ3: =VLOOKUP(RAND(),A103:C105,3,TRUE) -> 2 | AK3: =VLOOKUP(RAND(),A106:C108,3,TRUE) -> 0 | AL3: =VLOOKUP(RAND(),A52:C55,3,TRUE) -> 0 | AM3: =VLOOKUP(RAND(),A113:C114,3,TRUE) -> 0 | AN3: =VLOOKUP(RAND(),A115:C118,3,TRUE) -> 0 | AO3: =SUM(AJ3:AN3)*B6 -> 300
A4: 6-8 | B4: 100 | G4: 2 | H4: 0 | I4: 0 | J4: 0 | K4: 0 | L4: 0 | M4: 0 | N4: 2 | O4: 2 | P4: 0 | Q4: 0 | R4: 0 | S4: 0 | T4: 160 | U4: 2 | V4: 0 | W4: 0 | X4: 0 | Y4: 0 | Z4: 0 | AA4: 0 | AB4: 2 | AC4: 0 | AD4: 0 | AE4: 0 | AF4: 0 | AG4: 0 | AH4: 0 | AI4: 2 | AJ4: 0 | AK4: 0 | AL4: 0 | AM4: 0 | AN4: 0 | AO4: 0
A5: 8-12 | B5: 120 | G5: 3 | H5: 0 | I5: 3 | J5: 0 | K5: 0 | L5: 2 | M5: 300 | N5: 3 | O5: 0 | P5: 0 | Q5: 0 | R5: 0 | S5: 1 | T5: 80 | U5: 3 | V5: 0 | W5: 1 | X5: 0 | Y5: 0 | Z5: 0 | AA5: 100 | AB5: 3 | AC5: 0 | AD5: 0 | AE5: 0 | AF5: 0 | AG5: 0 | AH5: 0 | AI5: 3 | AJ5: 0 | AK5: 0 | AL5: 0 | AM5: 0 | AN5: 0 | AO5: 0
A6: 12-+ | B6: 150 | G6: 4 | H6: 1 | I6: 3 | J6: 2 | K6: 0 | L6: 0 | M6: 360 | N6: 4 | O6: 0 | P6: 1 | Q6: 1 | R6: 0 | S6: 0 | T6: 160 | U6: 4 | V6: 0 | W6: 0 | X6: 1 | Y6: 0 | Z6: 0 | AA6: 100 | AB6: 4 | AC6: 0 | AD6: 0 | AE6: 0 | AF6: 0 | AG6: 0 | AH6: 0 | AI6: 4 | AJ6: 0 | AK6: 0 | AL6: 0 | AM6: 0 | AN6: 2 | AO6: 300
A7: Snow events by Inches per month | G7: 5 | H7: 0 | I7: 1 | J7: 0 | K7: 3 | L7: 1 | M7: 300 | N7: 5 | O7: 0 | P7: 0 | Q7: 0 | R7: 0 | S7: 0 | T7: 0 | U7: 5 | V7: 0 | W7: 3 | X7: 0 | Y7: 0 | Z7: 0 | AA7: 300 | AB7: 5 | AC7: 0 | AD7: 0 | AE7: 0 | AF7: 0 | AG7: 0 | AH7: 0 | AI7: 5 | AJ7: 0 | AK7: 0 | AL7: 0 | AM7: 0 | AN7: 0 | AO7: 0
A8: 2-4 | G8: 6 | H8: 1 | I8: 2 | J8: 0 | K8: 0 | L8: 0 | M8: 180 | N8: 6 | O8: 2 | P8: 2 | Q8: 0 | R8: 0 | S8: 1 | T8: 400 | U8: 6 | V8: 0 | W8: 0 | X8: 1 | Y8: 0 | Z8: 0 | AA8: 100 | AB8: 6 | AC8: 1 | AD8: 1 | AE8: 0 | AF8: 0 | AG8: 0 | AH8: 240 | AI8: 6 | AJ8: 0 | AK8: 0 | AL8: 0 | AM8: 0 | AN8: 0 | AO8: 0
A9: Low end | B9: Upper end | C9: NOV | G9: 7 | H9: 1 | I9: 0 | J9: 1 | K9: 0 | L9: 0 | M9: 120 | N9: 7 | O9: 1 | P9: 0 | Q9: 1 | R9: 0 | S9: 1 | T9: 240 | U9: 7 | V9: 0 | W9: 0 | X9: 0 | Y9: 0 | Z9: 0 | AA9: 0 | AB9: 7 | AC9: 1 | AD9: 0 | AE9: 0 | AF9: 0 | AG9: 0 | AH9: 120 | AI9: 7 | AJ9: 0 | AK9: 0 | AL9: 0 | AM9: 0 | AN9: 0 | AO9: 0
A10: 0 | B10: 0.65217391 | C10: 0 | G10: 8 | H10: 0 | I10: 0 | J10: 1 | K10: 0 | L10: 0 | M10: 60 | N10: 8 | O10: 0 | P10: 1 | Q10: 2 | R10: 0 | S10: 0 | T10: 240 | U10: 8 | V10: 0 | W10: 0 | X10: 0 | Y10: 0 | Z10: 0 | AA10: 0 | AB10: 8 | AC10: 0 | AD10: 0 | AE10: 0 | AF10: 0 | AG10: 0 | AH10: 0 | AI10: 8 | AJ10: 2 | AK10: 0 | AL10: 1 | AM10: 0 | AN10: 0 | AO10: 450
A11: 0.65217391 | B11: 0.9057971 | C11: 1 | G11: 9 | H11: 0 | I11: 3 | J11: 3 | K11: 0 | L11: 2 | M11: 480 | N11: 9 | O11: 0 | P11: 0 | Q11: 3 | R11: 0 | S11: 0 | T11: 240 | U11: 9 | V11: 0 | W11: 0 | X11: 0 | Y11: 0 | Z11: 0 | AA11: 0 | AB11: 9 | AC11: 0 | AD11: 0 | AE11: 0 | AF11: 1 | AG11: 0 | AH11: 120 | AI11: 9 | AJ11: 0 | AK11: 0 | AL11: 0 | AM11: 0 | AN11: 0 | AO11: 0
A12: 0.9057971 | B12: 0.97826087 | C12: 2 | G12: 10 | H12: 0 | I12: 1 | J12: 4 | K12: 0 | L12: 2 | M12: 420 | N12: 10 | O12: 0 | P12: 0 | Q12: 1 | R12: 0 | S12: 2 | T12: 240 | U12: 10 | V12: 0 | W12: 0 | X12: 0 | Y12: 0 | Z12: 0 | AA12: 0 | AB12: 10 | AC12: 0 | AD12: 0 | AE12: 0 | AF12: 0 | AG12: 0 | AH12: 0 | AI12: 10 | AJ12: 0 | AK12: 0 | AL12: 0 | AM12: 0 | AN12: 0 | AO12: 0
A13: 0.97826087 | B13: 0.99275362 | C13: 3 | G13: 11 | H13: 0 | I13: 0 | J13: 2 | K13: 2 | L13: 0 | M13: 240 | N13: 11 | O13: 3 | P13: 0 | Q13: 1 | R13: 0 | S13: 0 | T13: 320 | U13: 11 | V13: 0 | W13: 0 | X13: 0 | Y13: 0 | Z13: 0 | AA13: 0 | AB13: 11 | AC13: 0 | AD13: 0 | AE13: 0 | AF13: 0 | AG13: 0 | AH13: 0 | AI13: 11 | AJ13: 0 | AK13: 0 | AL13: 0 | AM13: 0 | AN13: 0 | AO13: 0
A14: 0.99275362 | B14: 1 | C14: 4 | G14: 12 | H14: 0 | I14: 0 | J14: 2 | K14: 3 | L14: 1 | M14: 360 | N14: 12 | O14: 0 | P14: 0 | Q14: 0 | R14: 0 | S14: 0 | T14: 0 | U14: 12 | V14: 0 | W14: 1 | X14: 0 | Y14: 0 | Z14: 0 | AA14: 100 | AB14: 12 | AC14: 0 | AD14: 0 | AE14: 0 | AF14: 0 | AG14: 0 | AH14: 0 | AI14: 12 | AJ14: 0 | AK14: 0 | AL14: 0 | AM14: 0 | AN14: 0 | AO14: 0
A15: Low end | B15: Upper end | C15: DEC | G15: 13 | H15: 0 | I15: 2 | J15: 0 | K15: 4 | L15: 0 | M15: 360 | N15: 13 | O15: 0 | P15: 1 | Q15: 0 | R15: 1 | S15: 1 | T15: 240 | U15: 13 | V15: 0 | W15: 0 | X15: 0 | Y15: 0 | Z15: 0 | AA15: 0 | AB15: 13 | AC15: 0 | AD15: 0 | AE15: 0 | AF15: 0 | AG15: 0 | AH15: 0 | AI15: 13 | AJ15: 0 | AK15: 0 | AL15: 0 | AM15: 0 | AN15: 0 | AO15: 0
A16: 0 | B16: 0.49275362 | C16: 0 | G16: 14 | H16: 1 | I16: 2 | J16: 0 | K16: 0 | L16: 0 | M16: 180 | N16: 14 | O16: 0 | P16: 0 | Q16: 0 | R16: 0 | S16: 0 | T16: 0 | U16: 14 | V16: 0 | W16: 0 | X16: 0 | Y16: 0 | Z16: 0 | AA16: 0 | AB16: 14 | AC16: 0 | AD16: 0 | AE16: 0 | AF16: 0 | AG16: 0 | AH16: 0 | AI16: 14 | AJ16: 0 | AK16: 0 | AL16: 0 | AM16: 0 | AN16: 0 | AO16: 0
A17: 0.49275362 | B17: 0.7826087 | C17: 1 | G17: 15 | H17: 2 | I17: 0 | J17: 0 | K17: 0 | L17: 2 | M17: 240 | N17: 15 | O17: 0 | P17: 1 | Q17: 3 | R17: 0 | S17: 1 | T17: 400 | U17: 15 | V17: 1 | W17: 3 | X17: 0 | Y17: 0 | Z17: 0 | AA17: 400 | AB17: 15 | AC17: 0 | AD17: 0 | AE17: 0 | AF17: 0 | AG17: 0 | AH17: 0 | AI17: 15 | AJ17: 0 | AK17: 0 | AL17: 2 | AM17: 0 | AN17: 0 | AO17: 300
A18: 0.7826087 | B18: 0.92028986 | C18: 2 | G18: 16 | H18: 1 | I18: 2 | J18: 2 | K18: 2 | L18: 2 | M18: 540 | N18: 16 | O18: 0 | P18: 1 | Q18: 0 | R18: 0 | S18: 0 | T18: 80 | U18: 16 | V18: 0 | W18: 0 | X18: 0 | Y18: 0 | Z18: 0 | AA18: 0 | AB18: 16 | AC18: 0 | AD18: 0 | AE18: 0 | AF18: 0 | AG18: 1 | AH18: 120 | AI18: 16 | AJ18: 0 | AK18: 0 | AL18: 0 | AM18: 0 | AN18: 0 | AO18: 0
A19: 0.92028986 | B19: 0.97826087 | C19: 3 | G19: 17 | H19: 0 | I19: 0 | J19: 1 | K19: 0 | L19: 1 | M19: 120 | N19: 17 | O19: 0 | P19: 2 | Q19: 1 | R19: 0 | S19: 0 | T19: 240 | U19: 17 | V19: 0 | W19: 0 | X19: 0 | Y19: 1 | Z19: 0 | AA19: 100 | AB19: 17 | AC19: 0 | AD19: 0 | AE19: 0 | AF19: 1 | AG19: 0 | AH19: 120 | AI19: 17 | AJ19: 0 | AK19: 0 | AL19: 0 | AM19: 0 | AN19: 0 | AO19: 0
A20: 0.97826087 | B20: 0.99275362 | C20: 4 | G20: 18 | H20: 0 | I20: 1 | J20: 1 | K20: 0 | L20: 0 | M20: 120 | N20: 18 | O20: 0 | P20: 0 | Q20: 0 | R20: 0 | S20: 0 | T20: 0 | U20: 18 | V20: 0 | W20: 0 | X20: 0 | Y20: 0 | Z20: 0 | AA20: 0 | AB20: 18 | AC20: 0 | AD20: 0 | AE20: 0 | AF20: 0 | AG20: 0 | AH20: 0 | AI20: 18 | AJ20: 0 | AK20: 0 | AL20: 1 | AM20: 0 | AN20: 0 | AO20: 150
A21: 0.99275362 | B21: 1 | C21: 5 | G21: 19 | H21: 0 | I21: 2 | J21: 0 | K21: 3 | L21: 1 | M21: 360 | N21: 19 | O21: 0 | P21: 0 | Q21: 0 | R21: 3 | S21: 0 | T21: 240 | U21: 19 | V21: 0 | W21: 0 | X21: 0 | Y21: 0 | Z21: 0 | AA21: 0 | AB21: 19 | AC21: 0 | AD21: 0 | AE21: 0 | AF21: 0 | AG21: 0 | AH21: 0 | AI21: 19 | AJ21: 0 | AK21: 0 | AL21: 1 | AM21: 0 | AN21: 0 | AO21: 150
A22: Low end | B22: Upper end | C22: Jan | G22: 20 | H22: 0 | I22: 0 | J22: 1 | K22: 1 | L22: 0 | M22: 120 | N22: 20 | O22: 0 | P22: 0 | Q22: 0 | R22: 1 | S22: 0 | T22: 80 | U22: 20 | V22: 0 | W22: 1 | X22: 0 | Y22: 0 | Z22: 0 | AA22: 100 | AB22: 20 | AC22: 0 | AD22: 0 | AE22: 0 | AF22: 0 | AG22: 0 | AH22: 0 | AI22: 20 | AJ22: 0 | AK22: 0 | AL22: 1 | AM22: 0 | AN22: 0 | AO22: 150
A23: 0 | B23: 0.42028986 | C23: 0 | G23: 21 | H23: 0 | I23: 2 | J23: 1 | K23: 0 | L23: 1 | M23: 240 | N23: 21 | O23: 0 | P23: 0 | Q23: 0 | R23: 0 | S23: 1 | T23: 80 | U23: 21 | V23: 0 | W23: 0 | X23: 0 | Y23: 0 | Z23: 0 | AA23: 0 | AB23: 21 | AC23: 0 | AD23: 0 | AE23: 0 | AF23: 0 | AG23: 0 | AH23: 0 | AI23: 21 | AJ23: 0 | AK23: 0 | AL23: 2 | AM23: 0 | AN23: 0 | AO23: 300
A24: 0.42028986 | B24: 0.72463768 | C24: 1 | G24: 22 | H24: 1 | I24: 1 | J24: 3 | K24: 0 | L24: 0 | M24: 300 | N24: 22 | O24: 0 | P24: 0 | Q24: 0 | R24: 0 | S24: 0 | T24: 0 | U24: 22 | V24: 0 | W24: 0 | X24: 0 | Y24: 0 | Z24: 0 | AA24: 0 | AB24: 22 | AC24: 0 | AD24: 0 | AE24: 0 | AF24: 0 | AG24: 0 | AH24: 0 | AI24: 22 | AJ24: 0 | AK24: 0 | AL24: 0 | AM24: 0 | AN24: 0 | AO24: 0
A25: 0.72463768 | B25: 0.89855072 | C25: 2 | G25: 23 | H25: 1 | I25: 0 | J25: 3 | K25: 2 | L25: 2 | M25: 480 | N25: 23 | O25: 0 | P25: 0 | Q25: 0 | R25: 0 | S25: 0 | T25: 0 | U25: 23 | V25: 0 | W25: 0 | X25: 0 | Y25: 0 | Z25: 0 | AA25: 0 | AB25: 23 | AC25: 1 | AD25: 0 | AE25: 0 | AF25: 0 | AG25: 0 | AH25: 120 | AI25: 23 | AJ25: 0 | AK25: 0 | AL25: 0 | AM25: 0 | AN25: 0 | AO25: 0
A26: 0.89855072 | B26: 0.98550725 | C26: 3 | G26: 24 | H26: 0 | I26: 0 | J26: 2 | K26: 3 | L26: 1 | M26: 360 | N26: 24 | O26: 0 | P26: 1 | Q26: 0 | R26: 0 | S26: 1 | T26: 160 | U26: 24 | V26: 0 | W26: 0 | X26: 0 | Y26: 0 | Z26: 0 | AA26: 0 | AB26: 24 | AC26: 0 | AD26: 1 | AE26: 0 | AF26: 0 | AG26: 0 | AH26: 120 | AI26: 24 | AJ26: 0 | AK26: 0 | AL26: 0 | AM26: 0 | AN26: 0 | AO26: 0
A27: 0.98550725 | B27: 0.99275362 | C27: 4 | G27: 25 | H27: 2 | I27: 1 | J27: 2 | K27: 0 | L27: 0 | M27: 300 | N27: 25 | O27: 0 | P27: 1 | Q27: 2 | R27: 0 | S27: 0 | T27: 240 | U27: 25 | V27: 0 | W27: 0 | X27: 1 | Y27: 0 | Z27: 0 | AA27: 100 | AB27: 25 | AC27: 0 | AD27: 0 | AE27: 0 | AF27: 0 | AG27: 0 | AH27: 0 | AI27: 25 | AJ27: 0 | AK27: 0 | AL27: 0 | AM27: 0 | AN27: 0 | AO27: 0
A28: 0.99275362 | B28: 1 | C28: 5 | G28: 26 | H28: 0 | I28: 0 | J28: 2 | K28: 1 | L28: 2 | M28: 300 | N28: 26 | O28: 0 | P28: 0 | Q28: 0 | R28: 1 | S28: 0 | T28: 80 | U28: 26 | V28: 0 | W28: 0 | X28: 0 | Y28: 0 | Z28: 0 | AA28: 0 | AB28: 26 | AC28: 1 | AD28: 0 | AE28: 0 | AF28: 0 | AG28: 0 | AH28: 120 | AI28: 26 | AJ28: 0 | AK28: 0 | AL28: 1 | AM28: 0 | AN28: 0 | AO28: 150
A29: Low end | B29: Upper end | C29: Feb | G29: 27 | H29: 0 | I29: 2 | J29: 0 | K29: 2 | L29: 1 | M29: 300 | N29: 27 | O29: 0 | P29: 0 | Q29: 2 | R29: 0 | S29: 0 | T29: 160 | U29: 27 | V29: 0 | W29: 1 | X29: 1 | Y29: 0 | Z29: 0 | AA29: 200 | AB29: 27 | AC29: 1 | AD29: 0 | AE29: 0 | AF29: 0 | AG29: 0 | AH29: 120 | AI29: 27 | AJ29: 0 | AK29: 0 | AL29: 0 | AM29: 0 | AN29: 0 | AO29: 0
A30: 0 | B30: 0.45652174 | C30: 0 | G30: 28 | H30: 0 | I30: 0 | J30: 1 | K30: 0 | L30: 1 | M30: 120 | N30: 28 | O30: 0 | P30: 2 | Q30: 1 | R30: 0 | S30: 1 | T30: 320 | U30: 28 | V30: 0 | W30: 0 | X30: 0 | Y30: 0 | Z30: 1 | AA30: 100 | AB30: 28 | AC30: 0 | AD30: 0 | AE30: 0 | AF30: 0 | AG30: 0 | AH30: 0 | AI30: 28 | AJ30: 0 | AK30: 0 | AL30: 0 | AM30: 0 | AN30: 0 | AO30: 0
A31: 0.45652174 | B31: 0.57333333 | C31: 1 | G31: 29 | H31: 0 | I31: 0 | J31: 3 | K31: 0 | L31: 0 | M31: 180 | N31: 29 | O31: 2 | P31: 1 | Q31: 0 | R31: 0 | S31: 0 | T31: 240 | U31: 29 | V31: 0 | W31: 2 | X31: 0 | Y31: 0 | Z31: 0 | AA31: 200 | AB31: 29 | AC31: 0 | AD31: 0 | AE31: 0 | AF31: 0 | AG31: 0 | AH31: 0 | AI31: 29 | AJ31: 0 | AK31: 0 | AL31: 0 | AM31: 0 | AN31: 0 | AO31: 0
A32: 0.57333333 | B32: 0.78125 | C32: 2 | G32: 30 | H32: 0 | I32: 1 | J32: 0 | K32: 0 | L32: 0 | M32: 60 | N32: 30 | O32: 1 | P32: 1 | Q32: 0 | R32: 2 | S32: 0 | T32: 320 | U32: 30 | V32: 0 | W32: 0 | X32: 0 | Y32: 0 | Z32: 0 | AA32: 0 | AB32: 30 | AC32: 0 | AD32: 0 | AE32: 0 | AF32: 0 | AG32: 0 | AH32: 0 | AI32: 30 | AJ32: 0 | AK32: 0 | AL32: 0 | AM32: 0 | AN32: 0 | AO32: 0
A33: 0.78125 | B33: 0.85714286 | C33: 3 | G33: 31 | H33: 1 | I33: 0 | J33: 1 | K33: 3 | L33: 2 | M33: 420 | N33: 31 | O33: 0 | P33: 0 | Q33: 0 | R33: 0 | S33: 0 | T33: 0 | U33: 31 | V33: 0 | W33: 1 | X33: 0 | Y33: 0 | Z33: 0 | AA33: 100 | AB33: 31 | AC33: 0 | AD33: 0 | AE33: 0 | AF33: 0 | AG33: 0 | AH33: 0 | AI33: 31 | AJ33: 0 | AK33: 0 | AL33: 1 | AM33: 0 | AN33: 0 | AO33: 150
A34: 0.85714286 | B34: 1 | C34: 4 | G34: 32 | H34: 1 | I34: 1 | J34: 0 | K34: 4 | L34: 2 | M34: 480 | N34: 32 | O34: 1 | P34: 0 | Q34: 1 | R34: 0 | S34: 1 | T34: 240 | U34: 32 | V34: 0 | W34: 2 | X34: 0 | Y34: 0 | Z34: 0 | AA34: 200 | AB34: 32 | AC34: 0 | AD34: 0 | AE34: 0 | AF34: 0 | AG34: 1 | AH34: 120 | AI34: 32 | AJ34: 0 | AK34: 0 | AL34: 0 | AM34: 0 | AN34: 0 | AO34: 0
A35: Low end | B35: Upper end | C35: Mar | G35: 33 | H35: 1 | I35: 2 | J35: 2 | K35: 4 | L35: 0 | M35: 540 | N35: 33 | O35: 0 | P35: 0 | Q35: 1 | R35: 0 | S35: 0 | T35: 80 | U35: 33 | V35: 0 | W35: 0 | X35: 0 | Y35: 0 | Z35: 0 | AA35: 0 | AB35: 33 | AC35: 0 | AD35: 0 | AE35: 0 | AF35: 0 | AG35: 1 | AH35: 120 | AI35: 33 | AJ35: 0 | AK35: 0 | AL35: 0 | AM35: 0 | AN35: 0 | AO35: 0
A36: 0 | B36: 0.52898551 | C36: 0 | G36: 34 | H36: 3 | I36: 0 | J36: 1 | K36: 1 | L36: 0 | M36: 300 | N36: 34 | O36: 0 | P36: 1 | Q36: 0 | R36: 0 | S36: 1 | T36: 160 | U36: 34 | V36: 0 | W36: 0 | X36: 1 | Y36: 0 | Z36: 0 | AA36: 100 | AB36: 34 | AC36: 0 | AD36: 0 | AE36: 0 | AF36: 0 | AG36: 0 | AH36: 0 | AI36: 34 | AJ36: 0 | AK36: 0 | AL36: 0 | AM36: 0 | AN36: 0 | AO36: 0
A37: 0.52898551 | B37: 0.78985507 | C37: 1 | G37: 35 | H37: 1 | I37: 0 | J37: 1 | K37: 2 | L37: 0 | M37: 240 | N37: 35 | O37: 0 | P37: 0 | Q37: 0 | R37: 0 | S37: 0 | T37: 0 | U37: 35 | V37: 0 | W37: 1 | X37: 1 | Y37: 0 | Z37: 0 | AA37: 200 | AB37: 35 | AC37: 0 | AD37: 0 | AE37: 0 | AF37: 0 | AG37: 0 | AH37: 0 | AI37: 35 | AJ37: 0 | AK37: 0 | AL37: 1 | AM37: 0 | AN37: 0 | AO37: 150
A38: 0.78985507 | B38: 0.96376812 | C38: 2 | G38: 36 | H38: 0 | I38: 0 | J38: 1 | K38: 0 | L38: 4 | M38: 300 | N38: 36 | O38: 0 | P38: 0 | Q38: 0 | R38: 1 | S38: 0 | T38: 80 | U38: 36 | V38: 0 | W38: 0 | X38: 0 | Y38: 0 | Z38: 0 | AA38: 0 | AB38: 36 | AC38: 0 | AD38: 0 | AE38: 0 | AF38: 0 | AG38: 3 | AH38: 360 | AI38: 36 | AJ38: 0 | AK38: 0 | AL38: 0 | AM38: 0 | AN38: 0 | AO38: 0
A39: 0.96376812 | B39: 0.97826087 | C39: 3 | G39: 37 | H39: 0 | I39: 0 | J39: 0 | K39: 0 | L39: 0 | M39: 0 | N39: 37 | O39: 1 | P39: 0 | Q39: 1 | R39: 0 | S39: 0 | T39: 160 | U39: 37 | V39: 0 | W39: 0 | X39: 0 | Y39: 0 | Z39: 1 | AA39: 100 | AB39: 37 | AC39: 0 | AD39: 0 | AE39: 0 | AF39: 0 | AG39: 0 | AH39: 0 | AI39: 37 | AJ39: 0 | AK39: 0 | AL39: 1 | AM39: 0 | AN39: 0 | AO39: 150
A40: 0.97826087 | B40: 1 | C40: 4 | G40: 38 | H40: 0 | I40: 1 | J40: 3 | K40: 4 | L40: 4 | M40: 720 | N40: 38 | O40: 0 | P40: 1 | Q40: 2 | R40: 0 | S40: 2 | T40: 400 | U40: 38 | V40: 0 | W40: 1 | X40: 0 | Y40: 0 | Z40: 0 | AA40: 100 | AB40: 38 | AC40: 0 | AD40: 0 | AE40: 0 | AF40: 0 | AG40: 0 | AH40: 0 | AI40: 38 | AJ40: 0 | AK40: 0 | AL40: 0 | AM40: 0 | AN40: 0 | AO40: 0
...

Sheet 2 or greater
B1: Nov | C1: Dec | D1: Jan | E1: Feb | F1: Mar | H1: Nov | I1: Dec | J1: Jan | K1: Feb | L1: Mar | O1: Nov | P1: cont for NOV | Q1: Dec | R1: Count for DEC | S1: Jan | T1: Count of JAN | U1: Feb | V1: Count FEB | W1: Mar | X1: count of march
A2: 2021-2022 | B2: 0 | C2: 3 | D2: 3 | E2: 1 | F2: 1 | H2: =B2-'4 or greater'!B2-'6 or greater'!B2-'8 or greater'!B2-'12 or greater'!B2 -> 0 | I2: =C2-'4 or greater'!C2-'6 or greater'!C2-'8 or greater'!C2-'12 or greater'!C2 -> 0 | J2: =D2-'4 or greater'!D2-'6 or greater'!D2-'8 or greater'!D2-'12 or greater'!D2 -> 3 | K2: =E2-'4 or greater'!E2-'6 or greater'!E2-'8 or greater'!E2-'12 or greater'!E2 -> 0 | L2: =F2-'4 or greater'!F2-'6 or greater'!F2-'8 or greater'!F2-'12 or greater'!F2 -> 1 | O2: 2 | P2: =COUNTIF($H$2:$H$139,O2) -> 10 | W2: 0 | X2: 73
A3: 2020-2021 | B3: 2 | C3: 2 | D3: 2 | E3: 1 | F3: 1 | H3: =B3-'4 or greater'!B3-'6 or greater'!B3-'8 or greater'!B3-'12 or greater'!B3 -> 1 | I3: =C3-'4 or greater'!C3-'6 or greater'!C3-'8 or greater'!C3-'12 or greater'!C3 -> -1 | J3: =D3-'4 or greater'!D3-'6 or greater'!D3-'8 or greater'!D3-'12 or greater'!D3 -> 1 | K3: =E3-'4 or greater'!E3-'6 or greater'!E3-'8 or greater'!E3-'12 or greater'!E3 -> 1 | L3: =F3-'4 or greater'!F3-'6 or greater'!F3-'8 or greater'!F3-'12 or greater'!F3 -> 1 | O3: 1 | P3: =COUNTIF($H$2:$H$139,O3) -> 35 | S3: 0 | T3: 58 | W3: 1 | X3: =COUNTIF($L$2:$L$139,W3) -> 36
A4: 2019-2020 | B4: 3 | C4: 2 | D4: 1 | E4: 2 | F4: 0 | H4: =B4-'4 or greater'!B4-'6 or greater'!B4-'8 or greater'!B4-'12 or greater'!B4 -> 1 | I4: =C4-'4 or greater'!C4-'6 or greater'!C4-'8 or greater'!C4-'12 or greater'!C4 -> 1 | J4: =D4-'4 or greater'!D4-'6 or greater'!D4-'8 or greater'!D4-'12 or greater'!D4 -> 0 | K4: =E4-'4 or greater'!E4-'6 or greater'!E4-'8 or greater'!E4-'12 or greater'!E4 -> 1 | L4: =F4-'4 or greater'!F4-'6 or greater'!F4-'8 or greater'!F4-'12 or greater'!F4 -> 0 | O4: 0 | P4: 90 | S4: 2 | T4: =COUNTIF($J$2:$J$139,S4) -> 24 | U4: 0 | V4: 63 | W4: 2 | X4: =COUNTIF($L$2:$L$139,W4) -> 24
A5: 2018-2019 | B5: 0 | C5: 2 | D5: 2 | E5: 6 | F5: 2 | H5: =B5-'4 or greater'!B5-'6 or greater'!B5-'8 or greater'!B5-'12 or greater'!B5 -> 0 | I5: =C5-'4 or greater'!C5-'6 or greater'!C5-'8 or greater'!C5-'12 or greater'!C5 -> 2 | J5: =D5-'4 or greater'!D5-'6 or greater'!D5-'8 or greater'!D5-'12 or greater'!D5 -> 2 | K5: =E5-'4 or greater'!E5-'6 or greater'!E5-'8 or greater'!E5-'12 or greater'!E5 -> -1 | L5: =F5-'4 or greater'!F5-'6 or greater'!F5-'8 or greater'!F5-'12 or greater'!F5 -> 1 | O5: 3 | P5: =COUNTIF($H$2:$H$139,O5) -> 2 | Q5: 5 | R5: =COUNTIF($I$2:$I$139,Q5) -> 1 | S5: 5 | T5: =COUNTIF($J$2:$J$139,S5) -> 1 | U5: 4 | V5: =COUNTIF($K$2:$K$139,U5) -> 1 | W5: 3 | X5: =COUNTIF($L$2:$L$139,W5) -> 2
A6: 2017-2018 | B6: 0 | C6: 1 | D6: 4 | E6: 4 | F6: 1 | H6: =B6-'4 or greater'!B6-'6 or greater'!B6-'8 or greater'!B6-'12 or greater'!B6 -> 0 | I6: =C6-'4 or greater'!C6-'6 or greater'!C6-'8 or greater'!C6-'12 or greater'!C6 -> 1 | J6: =D6-'4 or greater'!D6-'6 or greater'!D6-'8 or greater'!D6-'12 or greater'!D6 -> 0 | K6: =E6-'4 or greater'!E6-'6 or greater'!E6-'8 or greater'!E6-'12 or greater'!E6 -> 2 | L6: =F6-'4 or greater'!F6-'6 or greater'!F6-'8 or greater'!F6-'12 or greater'!F6 -> 1 | Q6: 2 | R6: =COUNTIF($I$2:$I$139,Q6) -> 19 | S6: 4 | T6: =COUNTIF($J$2:$J$139,S6) -> 1 | U6: 3 | V6: =COUNTIF($K$2:$K$139,U6) -> 6 | W6: 4 | X6: =COUNTIF($L$2:$L$139,W6) -> 3
A7: 2016-2017 | B7: 0 | C7: 4 | D7: 3 | E7: 0 | F7: 1 | H7: =B7-'4 or greater'!B7-'6 or greater'!B7-'8 or greater'!B7-'12 or greater'!B7 -> 0 | I7: =C7-'4 or greater'!C7-'6 or greater'!C7-'8 or greater'!C7-'12 or greater'!C7 -> 2 | J7: =D7-'4 or greater'!D7-'6 or greater'!D7-'8 or greater'!D7-'12 or greater'!D7 -> 3 | K7: =E7-'4 or greater'!E7-'6 or greater'!E7-'8 or greater'!E7-'12 or greater'!E7 -> 0 | L7: =F7-'4 or greater'!F7-'6 or greater'!F7-'8 or greater'!F7-'12 or greater'!F7 -> 1 | Q7: 4 | R7: =COUNTIF($I$2:$I$139,Q7) -> 2 | S7: 3 | T7: =COUNTIF($J$2:$J$139,S7) -> 12 | U7: 1 | V7: =COUNTIF($K$2:$K$139,U7) -> 43
A8: 2015-2016 | B8: 1 | C8: 3 | D8: 0 | E8: 1 | F8: 1 | H8: =B8-'4 or greater'!B8-'6 or greater'!B8-'8 or greater'!B8-'12 or greater'!B8 -> 1 | I8: =C8-'4 or greater'!C8-'6 or greater'!C8-'8 or greater'!C8-'12 or greater'!C8 -> 3 | J8: =D8-'4 or greater'!D8-'6 or greater'!D8-'8 or greater'!D8-'12 or greater'!D8 -> 0 | K8: =E8-'4 or greater'!E8-'6 or greater'!E8-'8 or greater'!E8-'12 or greater'!E8 -> -2 | L8: =F8-'4 or greater'!F8-'6 or greater'!F8-'8 or greater'!F8-'12 or greater'!F8 -> 1 | O8: 4 | P8: =COUNTIF($H$2:$H$139,O8) -> 1 | Q8: 3 | R8: =COUNTIF($I$2:$I$139,Q8) -> 8 | U8: 2 | V8: =COUNTIF($K$2:$K$139,U8) -> 25
A9: 2014-2015 | B9: 2 | C9: 1 | D9: 1 | E9: 0 | F9: 1 | H9: =B9-'4 or greater'!B9-'6 or greater'!B9-'8 or greater'!B9-'12 or greater'!B9 -> 2 | I9: =C9-'4 or greater'!C9-'6 or greater'!C9-'8 or greater'!C9-'12 or greater'!C9 -> 1 | J9: =D9-'4 or greater'!D9-'6 or greater'!D9-'8 or greater'!D9-'12 or greater'!D9 -> 1 | K9: =E9-'4 or greater'!E9-'6 or greater'!E9-'8 or greater'!E9-'12 or greater'!E9 -> 0 | L9: =F9-'4 or greater'!F9-'6 or greater'!F9-'8 or greater'!F9-'12 or greater'!F9 -> 1 | Q9: 1 | R9: =COUNTIF($I$2:$I$139,Q9) -> 40 | S9: 1 | T9: =COUNTIF($J$2:$J$139,S9) -> 42
A10: 2013-2014 | B10: 0 | C10: 2 | D10: 4 | E10: 2 | F10: 1 | H10: =B10-'4 or greater'!B10-'6 or greater'!B10-'8 or greater'!B10-'12 or greater'!B10 -> 0 | I10: =C10-'4 or greater'!C10-'6 or greater'!C10-'8 or greater'!C10-'12 or greater'!C10 -> 1 | J10: =D10-'4 or greater'!D10-'6 or greater'!D10-'8 or greater'!D10-'12 or greater'!D10 -> 0 | K10: =E10-'4 or greater'!E10-'6 or greater'!E10-'8 or greater'!E10-'12 or greater'!E10 -> -2 | L10: =F10-'4 or greater'!F10-'6 or greater'!F10-'8 or greater'!F10-'12 or greater'!F10 -> 1 | Q10: 0 | R10: 68
A11: 2012-2013 | B11: 0 | C11: 1 | D11: 1 | E11: 3 | F11: 3 | H11: =B11-'4 or greater'!B11-'6 or greater'!B11-'8 or greater'!B11-'12 or greater'!B11 -> 0 | I11: =C11-'4 or greater'!C11-'6 or greater'!C11-'8 or greater'!C11-'12 or greater'!C11 -> -2 | J11: =D11-'4 or greater'!D11-'6 or greater'!D11-'8 or greater'!D11-'12 or greater'!D11 -> 1 | K11: =E11-'4 or greater'!E11-'6 or greater'!E11-'8 or greater'!E11-'12 or greater'!E11 -> 2 | L11: =F11-'4 or greater'!F11-'6 or greater'!F11-'8 or greater'!F11-'12 or greater'!F11 -> 2
A12: 2011-2012 | B12: 1 | C12: 1 | D12: 0 | E12: 1 | F12: 0 | H12: =B12-'4 or greater'!B12-'6 or greater'!B12-'8 or greater'!B12-'12 or greater'!B12 -> 1 | I12: =C12-'4 or greater'!C12-'6 or greater'!C12-'8 or greater'!C12-'12 or greater'!C12 -> 0 | J12: =D12-'4 or greater'!D12-'6 or greater'!D12-'8 or greater'!D12-'12 or greater'!D12 -> 0 | K12: =E12-'4 or greater'!E12-'6 or greater'!E12-'8 or greater'!E12-'12 or greater'!E12 -> 1 | L12: =F12-'4 or greater'!F12-'6 or greater'!F12-'8 or greater'!F12-'12 or greater'!F12 -> 0
A13: 2010-2011 | B13: 1 | C13: 5 | D13: 2 | E13: 2 | F13: 1 | H13: =B13-'4 or greater'!B13-'6 or greater'!B13-'8 or greater'!B13-'12 or greater'!B13 -> -1 | I13: =C13-'4 or greater'!C13-'6 or greater'!C13-'8 or greater'!C13-'12 or greater'!C13 -> -1 | J13: =D13-'4 or greater'!D13-'6 or greater'!D13-'8 or greater'!D13-'12 or greater'!D13 -> 1 | K13: =E13-'4 or greater'!E13-'6 or greater'!E13-'8 or greater'!E13-'12 or greater'!E13 -> -1 | L13: =F13-'4 or greater'!F13-'6 or greater'!F13-'8 or greater'!F13-'12 or greater'!F13 -> 0
A14: 2009-2010 | B14: 0 | C14: 5 | D14: 1 | E14: 2 | F14: 0 | H14: =B14-'4 or greater'!B14-'6 or greater'!B14-'8 or greater'!B14-'12 or greater'!B14 -> 0 | I14: =C14-'4 or greater'!C14-'6 or greater'!C14-'8 or greater'!C14-'12 or greater'!C14 -> 3 | J14: =D14-'4 or greater'!D14-'6 or greater'!D14-'8 or greater'!D14-'12 or greater'!D14 -> 1 | K14: =E14-'4 or greater'!E14-'6 or greater'!E14-'8 or greater'!E14-'12 or greater'!E14 -> 1 | L14: =F14-'4 or greater'!F14-'6 or greater'!F14-'8 or greater'!F14-'12 or greater'!F14 -> 0
A15: 2008-2009 | B15: 0 | C15: 4 | D15: 1 | E15: 3 | F15: 0 | H15: =B15-'4 or greater'!B15-'6 or greater'!B15-'8 or greater'!B15-'12 or greater'!B15 -> 0 | I15: =C15-'4 or greater'!C15-'6 or greater'!C15-'8 or greater'!C15-'12 or greater'!C15 -> 4 | J15: =D15-'4 or greater'!D15-'6 or greater'!D15-'8 or greater'!D15-'12 or greater'!D15 -> 0 | K15: =E15-'4 or greater'!E15-'6 or greater'!E15-'8 or greater'!E15-'12 or greater'!E15 -> 1 | L15: =F15-'4 or greater'!F15-'6 or greater'!F15-'8 or greater'!F15-'12 or greater'!F15 -> 0
A16: 2007-2008 | B16: 0 | C16: 4 | D16: 0 | E16: 0 | F16: 3 | H16: =B16-'4 or greater'!B16-'6 or greater'!B16-'8 or greater'!B16-'12 or greater'!B16 -> 0 | I16: =C16-'4 or greater'!C16-'6 or greater'!C16-'8 or greater'!C16-'12 or greater'!C16 -> 3 | J16: =D16-'4 or greater'!D16-'6 or greater'!D16-'8 or greater'!D16-'12 or greater'!D16 -> 0 | K16: =E16-'4 or greater'!E16-'6 or greater'!E16-'8 or greater'!E16-'12 or greater'!E16 -> 0 | L16: =F16-'4 or greater'!F16-'6 or greater'!F16-'8 or greater'!F16-'12 or greater'!F16 -> 2
A17: 2006-2007 | B17: 0 | C17: 1 | D17: 1 | E17: 2 | F17: 2 | H17: =B17-'4 or greater'!B17-'6 or greater'!B17-'8 or greater'!B17-'12 or greater'!B17 -> 0 | I17: =C17-'4 or greater'!C17-'6 or greater'!C17-'8 or greater'!C17-'12 or greater'!C17 -> 1 | J17: =D17-'4 or greater'!D17-'6 or greater'!D17-'8 or greater'!D17-'12 or greater'!D17 -> 1 | K17: =E17-'4 or greater'!E17-'6 or greater'!E17-'8 or greater'!E17-'12 or greater'!E17 -> 1 | L17: =F17-'4 or greater'!F17-'6 or greater'!F17-'8 or greater'!F17-'12 or greater'!F17 -> -1
A18: 2005-2006 | B18: 1 | C18: 3 | D18: 0 | E18: 0 | F18: 3 | H18: =B18-'4 or greater'!B18-'6 or greater'!B18-'8 or greater'!B18-'12 or greater'!B18 -> 1 | I18: =C18-'4 or greater'!C18-'6 or greater'!C18-'8 or greater'!C18-'12 or greater'!C18 -> 2 | J18: =D18-'4 or greater'!D18-'6 or greater'!D18-'8 or greater'!D18-'12 or greater'!D18 -> 0 | K18: =E18-'4 or greater'!E18-'6 or greater'!E18-'8 or greater'!E18-'12 or greater'!E18 -> 0 | L18: =F18-'4 or greater'!F18-'6 or greater'!F18-'8 or greater'!F18-'12 or greater'!F18 -> -1
A19: 2004-2005 | B19: 0 | C19: 0 | D19: 1 | E19: 1 | F19: 1 | H19: =B19-'4 or greater'!B19-'6 or greater'!B19-'8 or greater'!B19-'12 or greater'!B19 -> 0 | I19: =C19-'4 or greater'!C19-'6 or greater'!C19-'8 or greater'!C19-'12 or greater'!C19 -> 0 | J19: =D19-'4 or greater'!D19-'6 or greater'!D19-'8 or greater'!D19-'12 or greater'!D19 -> 0 | K19: =E19-'4 or greater'!E19-'6 or greater'!E19-'8 or greater'!E19-'12 or greater'!E19 -> 1 | L19: =F19-'4 or greater'!F19-'6 or greater'!F19-'8 or greater'!F19-'12 or greater'!F19 -> 0
A20: 2003-2004 | B20: 1 | C20: 2 | D20: 1 | E20: 3 | F20: 1 | H20: =B20-'4 or greater'!B20-'6 or greater'!B20-'8 or greater'!B20-'12 or greater'!B20 -> 0 | I20: =C20-'4 or greater'!C20-'6 or greater'!C20-'8 or greater'!C20-'12 or greater'!C20 -> -1 | J20: =D20-'4 or greater'!D20-'6 or greater'!D20-'8 or greater'!D20-'12 or greater'!D20 -> -1 | K20: =E20-'4 or greater'!E20-'6 or greater'!E20-'8 or greater'!E20-'12 or greater'!E20 -> 0 | L20: =F20-'4 or greater'!F20-'6 or greater'!F20-'8 or greater'!F20-'12 or greater'!F20 -> -1
A21: 2002-2003 | B21: 0 | C21: 0 | D21: 0 | E21: 3 | F21: 3 | H21: =B21-'4 or greater'!B21-'6 or greater'!B21-'8 or greater'!B21-'12 or greater'!B21 -> 0 | I21: =C21-'4 or greater'!C21-'6 or greater'!C21-'8 or greater'!C21-'12 or greater'!C21 -> 0 | J21: =D21-'4 or greater'!D21-'6 or greater'!D21-'8 or greater'!D21-'12 or greater'!D21 -> 0 | K21: =E21-'4 or greater'!E21-'6 or greater'!E21-'8 or greater'!E21-'12 or greater'!E21 -> 3 | L21: =F21-'4 or greater'!F21-'6 or greater'!F21-'8 or greater'!F21-'12 or greater'!F21 -> 2
A22: 2001-2002 | B22: 2 | C22: 2 | D22: 1 | E22: 0 | F22: 1 | H22: =B22-'4 or greater'!B22-'6 or greater'!B22-'8 or greater'!B22-'12 or greater'!B22 -> 1 | I22: =C22-'4 or greater'!C22-'6 or greater'!C22-'8 or greater'!C22-'12 or greater'!C22 -> 2 | J22: =D22-'4 or greater'!D22-'6 or greater'!D22-'8 or greater'!D22-'12 or greater'!D22 -> 1 | K22: =E22-'4 or greater'!E22-'6 or greater'!E22-'8 or greater'!E22-'12 or greater'!E22 -> 0 | L22: =F22-'4 or greater'!F22-'6 or greater'!F22-'8 or greater'!F22-'12 or greater'!F22 -> -2
... A139: 1884-1885 | B139: 1 | C139: 3 | D139: 1 | E139: 0 | F139: 0 | H139: =B139-'4 or greater'!B139-'6 or greater'!B139-'8 or greater'!B139-'12 or greater'!B139 -> 0 | I139: =C139-'4 or greater'!C139-'6 or greater'!C139-'8 or greater'!C139-'12 or greater'!C139 -> 2 | J139: =D139-'4 or greater'!D139-'6 or greater'!D139-'8 or greater'!D139-'12 or greater'!D139 -> 1 | K139: =E139-'4 or greater'!E139-'6 or greater'!E139-'8 or greater'!E139-'12 or greater'!E139 -> 0 | L139: =F139-'4 or greater'!F139-'6 or greater'!F139-'8 or greater'!F139-'12 or greater'!F139 -> 0

Sheet 4 or greater
B1: Nov | C1: Dec | D1: Jan | E1: Feb | F1: Mar | H1: Nov | I1: Dec | J1: Jan | K1: Feb | L1: Mar | N1: Nov | O1: Count NOV | P1: Dec | R1: Jan | T1: Feb | V1: Mar
A2: 2021-2022 | B2: 0 | C2: 1 | D2: 0 | E2: 1 | F2: 0 | H2: =B2-'6 or greater'!B2-'8 or greater'!B2-'12 or greater'!B2 -> 0 | I2: =C2-'6 or greater'!C2-'8 or greater'!C2-'12 or greater'!C2 -> -1 | J2: =D2-'6 or greater'!D2-'8 or greater'!D2-'12 or greater'!D2 -> 0 | K2: =E2-'6 or greater'!E2-'8 or greater'!E2-'12 or greater'!E2 -> 1 | L2: =F2-'6 or greater'!F2-'8 or greater'!F2-'12 or greater'!F2 -> 0 | N2: 3 | O2: =COUNTIF($H$2:$H$139,N2) -> 1 | T2: 0 | U2: 109 | V2: 0 | W2: 106
A3: 2020-2021 | B3: 1 | C3: 1 | D3: 1 | E3: 0 | F3: 0 | H3: =B3-'6 or greater'!B3-'8 or greater'!B3-'12 or greater'!B3 -> 1 | I3: =C3-'6 or greater'!C3-'8 or greater'!C3-'12 or greater'!C3 -> -1 | J3: =D3-'6 or greater'!D3-'8 or greater'!D3-'12 or greater'!D3 -> 1 | K3: =E3-'6 or greater'!E3-'8 or greater'!E3-'12 or greater'!E3 -> 0 | L3: =F3-'6 or greater'!F3-'8 or greater'!F3-'12 or greater'!F3 -> 0 | R3: 0 | S3: 107 | T3: 1 | U3: =COUNTIF($K$2:$K$139,T3) -> 23 | V3: 1 | W3: =COUNTIF($L$2:$L$139,V3) -> 30
A4: 2019-2020 | B4: 1 | C4: 1 | D4: 1 | E4: 1 | F4: 0 | H4: =B4-'6 or greater'!B4-'8 or greater'!B4-'12 or greater'!B4 -> 0 | I4: =C4-'6 or greater'!C4-'8 or greater'!C4-'12 or greater'!C4 -> 1 | J4: =D4-'6 or greater'!D4-'8 or greater'!D4-'12 or greater'!D4 -> 1 | K4: =E4-'6 or greater'!E4-'8 or greater'!E4-'12 or greater'!E4 -> 1 | L4: =F4-'6 or greater'!F4-'8 or greater'!F4-'12 or greater'!F4 -> 0 | N4: 2 | O4: =COUNTIF($H$2:$H$139,N4) -> 2 | P4: 2 | Q4: =COUNTIF($I$2:$I$139,P4) -> 4 | R4: 2 | S4: =COUNTIF($J$2:$J$139,R4) -> 6 | T4: 2 | U4: =COUNTIF($K$2:$K$139,T4) -> 4 | V4: 2 | W4: =COUNTIF($L$2:$L$139,V4) -> 2
A5: 2018-2019 | B5: 0 | C5: 0 | D5: 0 | E5: 5 | F5: 1 | H5: =B5-'6 or greater'!B5-'8 or greater'!B5-'12 or greater'!B5 -> 0 | I5: =C5-'6 or greater'!C5-'8 or greater'!C5-'12 or greater'!C5 -> 0 | J5: =D5-'6 or greater'!D5-'8 or greater'!D5-'12 or greater'!D5 -> 0 | K5: =E5-'6 or greater'!E5-'8 or greater'!E5-'12 or greater'!E5 -> 3 | L5: =F5-'6 or greater'!F5-'8 or greater'!F5-'12 or greater'!F5 -> 1 | M5: =SUM(W2,#REF!,#REF!,#REF!) -> #REF! | R5: 1 | S5: =COUNTIF($J$2:$J$139,R5) -> 24 | T5: 3 | U5: =COUNTIF($K$2:$K$139,T5) -> 2
A6: 2017-2018 | B6: 0 | C6: 0 | D6: 1 | E6: 1 | F6: 0 | H6: =B6-'6 or greater'!B6-'8 or greater'!B6-'12 or greater'!B6 -> 0 | I6: =C6-'6 or greater'!C6-'8 or greater'!C6-'12 or greater'!C6 -> 0 | J6: =D6-'6 or greater'!D6-'8 or greater'!D6-'12 or greater'!D6 -> -2 | K6: =E6-'6 or greater'!E6-'8 or greater'!E6-'12 or greater'!E6 -> 0 | L6: =F6-'6 or greater'!F6-'8 or greater'!F6-'12 or greater'!F6 -> 0 | N6: 0 | O6: 112 | P6: 1 | Q6: =COUNTIF($I$2:$I$139,P6) -> 25 | R6: 3 | S6: =COUNTIF($J$2:$J$139,R6) -> 1
A7: 2016-2017 | B7: 0 | C7: 2 | D7: 0 | E7: 0 | F7: 0 | H7: =B7-'6 or greater'!B7-'8 or greater'!B7-'12 or greater'!B7 -> 0 | I7: =C7-'6 or greater'!C7-'8 or greater'!C7-'12 or greater'!C7 -> 2 | J7: =D7-'6 or greater'!D7-'8 or greater'!D7-'12 or greater'!D7 -> 0 | K7: =E7-'6 or greater'!E7-'8 or greater'!E7-'12 or greater'!E7 -> 0 | L7: =F7-'6 or greater'!F7-'8 or greater'!F7-'12 or greater'!F7 -> 0 | P7: 0 | Q7: 109
A8: 2015-2016 | B8: 0 | C8: 0 | D8: 0 | E8: 1 | F8: 0 | H8: =B8-'6 or greater'!B8-'8 or greater'!B8-'12 or greater'!B8 -> 0 | I8: =C8-'6 or greater'!C8-'8 or greater'!C8-'12 or greater'!C8 -> 0 | J8: =D8-'6 or greater'!D8-'8 or greater'!D8-'12 or greater'!D8 -> 0 | K8: =E8-'6 or greater'!E8-'8 or greater'!E8-'12 or greater'!E8 -> -1 | L8: =F8-'6 or greater'!F8-'8 or greater'!F8-'12 or greater'!F8 -> 0 | N8: 1 | O8: =COUNTIF($H$2:$H$139,N8) -> 23
A9: 2014-2015 | B9: 0 | C9: 0 | D9: 0 | E9: 0 | F9: 0 | H9: =B9-'6 or greater'!B9-'8 or greater'!B9-'12 or greater'!B9 -> 0 | I9: =C9-'6 or greater'!C9-'8 or greater'!C9-'12 or greater'!C9 -> 0 | J9: =D9-'6 or greater'!D9-'8 or greater'!D9-'12 or greater'!D9 -> 0 | K9: =E9-'6 or greater'!E9-'8 or greater'!E9-'12 or greater'!E9 -> 0 | L9: =F9-'6 or greater'!F9-'8 or greater'!F9-'12 or greater'!F9 -> 0
A10: 2013-2014 | B10: 0 | C10: 1 | D10: 3 | E10: 2 | F10: 0 | H10: =B10-'6 or greater'!B10-'8 or greater'!B10-'12 or greater'!B10 -> 0 | I10: =C10-'6 or greater'!C10-'8 or greater'!C10-'12 or greater'!C10 -> 1 | J10: =D10-'6 or greater'!D10-'8 or greater'!D10-'12 or greater'!D10 -> 2 | K10: =E10-'6 or greater'!E10-'8 or greater'!E10-'12 or greater'!E10 -> 0 | L10: =F10-'6 or greater'!F10-'8 or greater'!F10-'12 or greater'!F10 -> 0
A11: 2012-2013 | B11: 0 | C11: 1 | D11: 0 | E11: 1 | F11: 1 | H11: =B11-'6 or greater'!B11-'8 or greater'!B11-'12 or greater'!B11 -> 0 | I11: =C11-'6 or greater'!C11-'8 or greater'!C11-'12 or greater'!C11 -> -1 | J11: =D11-'6 or greater'!D11-'8 or greater'!D11-'12 or greater'!D11 -> 0 | K11: =E11-'6 or greater'!E11-'8 or greater'!E11-'12 or greater'!E11 -> 1 | L11: =F11-'6 or greater'!F11-'8 or greater'!F11-'12 or greater'!F11 -> 1
A12: 2011-2012 | B12: 0 | C12: 1 | D12: 0 | E12: 0 | F12: 0 | H12: =B12-'6 or greater'!B12-'8 or greater'!B12-'12 or greater'!B12 -> 0 | I12: =C12-'6 or greater'!C12-'8 or greater'!C12-'12 or greater'!C12 -> 1 | J12: =D12-'6 or greater'!D12-'8 or greater'!D12-'12 or greater'!D12 -> 0 | K12: =E12-'6 or greater'!E12-'8 or greater'!E12-'12 or greater'!E12 -> 0 | L12: =F12-'6 or greater'!F12-'8 or greater'!F12-'12 or greater'!F12 -> 0
A13: 2010-2011 | B13: 1 | C13: 3 | D13: 1 | E13: 1 | F13: 1 | H13: =B13-'6 or greater'!B13-'8 or greater'!B13-'12 or greater'!B13 -> 0 | I13: =C13-'6 or greater'!C13-'8 or greater'!C13-'12 or greater'!C13 -> 0 | J13: =D13-'6 or greater'!D13-'8 or greater'!D13-'12 or greater'!D13 -> 1 | K13: =E13-'6 or greater'!E13-'8 or greater'!E13-'12 or greater'!E13 -> -1 | L13: =F13-'6 or greater'!F13-'8 or greater'!F13-'12 or greater'!F13 -> 1
A14: 2009-2010 | B14: 0 | C14: 2 | D14: 0 | E14: 1 | F14: 0 | H14: =B14-'6 or greater'!B14-'8 or greater'!B14-'12 or greater'!B14 -> 0 | I14: =C14-'6 or greater'!C14-'8 or greater'!C14-'12 or greater'!C14 -> 2 | J14: =D14-'6 or greater'!D14-'8 or greater'!D14-'12 or greater'!D14 -> 0 | K14: =E14-'6 or greater'!E14-'8 or greater'!E14-'12 or greater'!E14 -> 1 | L14: =F14-'6 or greater'!F14-'8 or greater'!F14-'12 or greater'!F14 -> 0
A15: 2008-2009 | B15: 0 | C15: 0 | D15: 1 | E15: 1 | F15: 0 | H15: =B15-'6 or greater'!B15-'8 or greater'!B15-'12 or greater'!B15 -> 0 | I15: =C15-'6 or greater'!C15-'8 or greater'!C15-'12 or greater'!C15 -> 0 | J15: =D15-'6 or greater'!D15-'8 or greater'!D15-'12 or greater'!D15 -> 1 | K15: =E15-'6 or greater'!E15-'8 or greater'!E15-'12 or greater'!E15 -> 0 | L15: =F15-'6 or greater'!F15-'8 or greater'!F15-'12 or greater'!F15 -> 0
A16: 2007-2008 | B16: 0 | C16: 1 | D16: 0 | E16: 0 | F16: 1 | H16: =B16-'6 or greater'!B16-'8 or greater'!B16-'12 or greater'!B16 -> 0 | I16: =C16-'6 or greater'!C16-'8 or greater'!C16-'12 or greater'!C16 -> 1 | J16: =D16-'6 or greater'!D16-'8 or greater'!D16-'12 or greater'!D16 -> 0 | K16: =E16-'6 or greater'!E16-'8 or greater'!E16-'12 or greater'!E16 -> 0 | L16: =F16-'6 or greater'!F16-'8 or greater'!F16-'12 or greater'!F16 -> 1
A17: 2006-2007 | B17: 0 | C17: 0 | D17: 0 | E17: 1 | F17: 1 | H17: =B17-'6 or greater'!B17-'8 or greater'!B17-'12 or greater'!B17 -> 0 | I17: =C17-'6 or greater'!C17-'8 or greater'!C17-'12 or greater'!C17 -> 0 | J17: =D17-'6 or greater'!D17-'8 or greater'!D17-'12 or greater'!D17 -> 0 | K17: =E17-'6 or greater'!E17-'8 or greater'!E17-'12 or greater'!E17 -> 1 | L17: =F17-'6 or greater'!F17-'8 or greater'!F17-'12 or greater'!F17 -> -1
A18: 2005-2006 | B18: 0 | C18: 1 | D18: 0 | E18: 0 | F18: 2 | H18: =B18-'6 or greater'!B18-'8 or greater'!B18-'12 or greater'!B18 -> 0 | I18: =C18-'6 or greater'!C18-'8 or greater'!C18-'12 or greater'!C18 -> 1 | J18: =D18-'6 or greater'!D18-'8 or greater'!D18-'12 or greater'!D18 -> 0 | K18: =E18-'6 or greater'!E18-'8 or greater'!E18-'12 or greater'!E18 -> 0 | L18: =F18-'6 or greater'!F18-'8 or greater'!F18-'12 or greater'!F18 -> 0
A19: 2004-2005 | B19: 0 | C19: 0 | D19: 1 | E19: 0 | F19: 1 | H19: =B19-'6 or greater'!B19-'8 or greater'!B19-'12 or greater'!B19 -> 0 | I19: =C19-'6 or greater'!C19-'8 or greater'!C19-'12 or greater'!C19 -> 0 | J19: =D19-'6 or greater'!D19-'8 or greater'!D19-'12 or greater'!D19 -> 1 | K19: =E19-'6 or greater'!E19-'8 or greater'!E19-'12 or greater'!E19 -> 0 | L19: =F19-'6 or greater'!F19-'8 or greater'!F19-'12 or greater'!F19 -> 1
A20: 2003-2004 | B20: 1 | C20: 1 | D20: 1 | E20: 2 | F20: 1 | H20: =B20-'6 or greater'!B20-'8 or greater'!B20-'12 or greater'!B20 -> 1 | I20: =C20-'6 or greater'!C20-'8 or greater'!C20-'12 or greater'!C20 -> -1 | J20: =D20-'6 or greater'!D20-'8 or greater'!D20-'12 or greater'!D20 -> 0 | K20: =E20-'6 or greater'!E20-'8 or greater'!E20-'12 or greater'!E20 -> 1 | L20: =F20-'6 or greater'!F20-'8 or greater'!F20-'12 or greater'!F20 -> 0
... A139: 1884-1885 | B139: 1 | C139: 1 | D139: 0 | E139: 0 | F139: 0 | H139: =B139-'6 or greater'!B139-'8 or greater'!B139-'12 or greater'!B139 -> 1 | I139: =C139-'6 or greater'!C139-'8 or greater'!C139-'12 or greater'!C139 -> 1 | J139: =D139-'6 or greater'!D139-'8 or greater'!D139-'12 or greater'!D139 -> 0 | K139: =E139-'6 or greater'!E139-'8 or greater'!E139-'12 or greater'!E139 -> 0 | L139: =F139-'6 or greater'!F139-'8 or greater'!F139-'12 or greater'!F139 -> 0

Sheet 6 or greater
B1: Nov | C1: Dec | D1: Jan | E1: Feb | F1: Mar | H1: Nov | I1: Dec | J1: Jan | K1: Feb | L1: Mar | P1: Nov | Q1: count for NOV | R1: Dec | S1: count for dec | T1: Jan | U1: count for Jan | V1: Feb | W1: count for feb | X1: Mar | Y1: count for marc
A2: 2021-2022 | B2: 0 | C2: 1 | D2: 0 | E2: 0 | F2: 0 | H2: =B2-'8 or greater'!B2-'12 or greater'!B2 -> 0 | I2: =C2-'8 or greater'!C2-'12 or greater'!C2 -> 0 | J2: =D2-'8 or greater'!D2-'12 or greater'!D2 -> 0 | K2: =E2-'8 or greater'!E2-'12 or greater'!E2 -> 0 | L2: =F2-'8 or greater'!F2-'12 or greater'!F2 -> 0 | P2: 0 | Q2: 129 | R2: 0 | S2: 123 | T2: 0 | U2: 123 | V2: 0 | W2: =COUNTIF($K$2:$K$140,V2) -> 126 | X2: 0 | Y2: 122
A3: 2020-2021 | B3: 0 | C3: 1 | D3: 0 | E3: 0 | F3: 0 | H3: =B3-'8 or greater'!B3-'12 or greater'!B3 -> 0 | I3: =C3-'8 or greater'!C3-'12 or greater'!C3 -> 0 | J3: =D3-'8 or greater'!D3-'12 or greater'!D3 -> 0 | K3: =E3-'8 or greater'!E3-'12 or greater'!E3 -> 0 | L3: =F3-'8 or greater'!F3-'12 or greater'!F3 -> 0 | P3: 1 | Q3: =COUNTIF($H$2:$H$140,P3) -> 9 | R3: 3 | S3: =COUNTIF($I$2:$I$140,R3) -> 1 | T3: 1 | U3: =COUNTIF($J$2:$J$140,T3) -> 15 | V3: 1 | W3: =COUNTIF($K$2:$K$140,V3) -> 11 | X3: 1 | Y3: =COUNTIF($L$2:$L$140,X3) -> 16
A4: 2019-2020 | B4: 1 | C4: 0 | D4: 0 | E4: 0 | F4: 0 | H4: =B4-'8 or greater'!B4-'12 or greater'!B4 -> 1 | I4: =C4-'8 or greater'!C4-'12 or greater'!C4 -> 0 | J4: =D4-'8 or greater'!D4-'12 or greater'!D4 -> 0 | K4: =E4-'8 or greater'!E4-'12 or greater'!E4 -> 0 | L4: =F4-'8 or greater'!F4-'12 or greater'!F4 -> 0 | R4: 1 | S4: =COUNTIF($I$2:$I$140,R4) -> 12 | V4: 2 | W4: =COUNTIF($K$2:$K$140,V4) -> 1
A5: 2018-2019 | B5: 0 | C5: 0 | D5: 0 | E5: 1 | F5: 0 | H5: =B5-'8 or greater'!B5-'12 or greater'!B5 -> 0 | I5: =C5-'8 or greater'!C5-'12 or greater'!C5 -> 0 | J5: =D5-'8 or greater'!D5-'12 or greater'!D5 -> 0 | K5: =E5-'8 or greater'!E5-'12 or greater'!E5 -> 0 | L5: =F5-'8 or greater'!F5-'12 or greater'!F5 -> 0 | R5: 2 | S5: =COUNTIF($I$2:$I$140,R5) -> 2
A6: 2017-2018 | B6: 0 | C6: 0 | D6: 1 | E6: 1 | F6: 0 | H6: =B6-'8 or greater'!B6-'12 or greater'!B6 -> 0 | I6: =C6-'8 or greater'!C6-'12 or greater'!C6 -> 0 | J6: =D6-'8 or greater'!D6-'12 or greater'!D6 -> -1 | K6: =E6-'8 or greater'!E6-'12 or greater'!E6 -> 1 | L6: =F6-'8 or greater'!F6-'12 or greater'!F6 -> 0
A7: 2016-2017 | B7: 0 | C7: 0 | D7: 0 | E7: 0 | F7: 0 | H7: =B7-'8 or greater'!B7-'12 or greater'!B7 -> 0 | I7: =C7-'8 or greater'!C7-'12 or greater'!C7 -> 0 | J7: =D7-'8 or greater'!D7-'12 or greater'!D7 -> 0 | K7: =E7-'8 or greater'!E7-'12 or greater'!E7 -> 0 | L7: =F7-'8 or greater'!F7-'12 or greater'!F7 -> 0
A8: 2015-2016 | B8: 0 | C8: 0 | D8: 0 | E8: 1 | F8: 0 | H8: =B8-'8 or greater'!B8-'12 or greater'!B8 -> 0 | I8: =C8-'8 or greater'!C8-'12 or greater'!C8 -> 0 | J8: =D8-'8 or greater'!D8-'12 or greater'!D8 -> 0 | K8: =E8-'8 or greater'!E8-'12 or greater'!E8 -> 0 | L8: =F8-'8 or greater'!F8-'12 or greater'!F8 -> 0
A9: 2014-2015 | B9: 0 | C9: 0 | D9: 0 | E9: 0 | F9: 0 | H9: =B9-'8 or greater'!B9-'12 or greater'!B9 -> 0 | I9: =C9-'8 or greater'!C9-'12 or greater'!C9 -> 0 | J9: =D9-'8 or greater'!D9-'12 or greater'!D9 -> 0 | K9: =E9-'8 or greater'!E9-'12 or greater'!E9 -> 0 | L9: =F9-'8 or greater'!F9-'12 or greater'!F9 -> 0
A10: 2013-2014 | B10: 0 | C10: 0 | D10: 1 | E10: 1 | F10: 0 | H10: =B10-'8 or greater'!B10-'12 or greater'!B10 -> 0 | I10: =C10-'8 or greater'!C10-'12 or greater'!C10 -> 0 | J10: =D10-'8 or greater'!D10-'12 or greater'!D10 -> 1 | K10: =E10-'8 or greater'!E10-'12 or greater'!E10 -> 0 | L10: =F10-'8 or greater'!F10-'12 or greater'!F10 -> 0
A11: 2012-2013 | B11: 0 | C11: 1 | D11: 0 | E11: 0 | F11: 0 | H11: =B11-'8 or greater'!B11-'12 or greater'!B11 -> 0 | I11: =C11-'8 or greater'!C11-'12 or greater'!C11 -> 0 | J11: =D11-'8 or greater'!D11-'12 or greater'!D11 -> 0 | K11: =E11-'8 or greater'!E11-'12 or greater'!E11 -> 0 | L11: =F11-'8 or greater'!F11-'12 or greater'!F11 -> 0
A12: 2011-2012 | B12: 0 | C12: 0 | D12: 0 | E12: 0 | F12: 0 | H12: =B12-'8 or greater'!B12-'12 or greater'!B12 -> 0 | I12: =C12-'8 or greater'!C12-'12 or greater'!C12 -> 0 | J12: =D12-'8 or greater'!D12-'12 or greater'!D12 -> 0 | K12: =E12-'8 or greater'!E12-'12 or greater'!E12 -> 0 | L12: =F12-'8 or greater'!F12-'12 or greater'!F12 -> 0
A13: 2010-2011 | B13: 1 | C13: 1 | D13: 0 | E13: 1 | F13: 0 | H13: =B13-'8 or greater'!B13-'12 or greater'!B13 -> 1 | I13: =C13-'8 or greater'!C13-'12 or greater'!C13 -> -1 | J13: =D13-'8 or greater'!D13-'12 or greater'!D13 -> 0 | K13: =E13-'8 or greater'!E13-'12 or greater'!E13 -> 0 | L13: =F13-'8 or greater'!F13-'12 or greater'!F13 -> 0
A14: 2009-2010 | B14: 0 | C14: 0 | D14: 0 | E14: 0 | F14: 0 | H14: =B14-'8 or greater'!B14-'12 or greater'!B14 -> 0 | I14: =C14-'8 or greater'!C14-'12 or greater'!C14 -> 0 | J14: =D14-'8 or greater'!D14-'12 or greater'!D14 -> 0 | K14: =E14-'8 or greater'!E14-'12 or greater'!E14 -> 0 | L14: =F14-'8 or greater'!F14-'12 or greater'!F14 -> 0
A15: 2008-2009 | B15: 0 | C15: 0 | D15: 0 | E15: 1 | F15: 0 | H15: =B15-'8 or greater'!B15-'12 or greater'!B15 -> 0 | I15: =C15-'8 or greater'!C15-'12 or greater'!C15 -> 0 | J15: =D15-'8 or greater'!D15-'12 or greater'!D15 -> 0 | K15: =E15-'8 or greater'!E15-'12 or greater'!E15 -> 1 | L15: =F15-'8 or greater'!F15-'12 or greater'!F15 -> 0
A16: 2007-2008 | B16: 0 | C16: 0 | D16: 0 | E16: 0 | F16: 0 | H16: =B16-'8 or greater'!B16-'12 or greater'!B16 -> 0 | I16: =C16-'8 or greater'!C16-'12 or greater'!C16 -> 0 | J16: =D16-'8 or greater'!D16-'12 or greater'!D16 -> 0 | K16: =E16-'8 or greater'!E16-'12 or greater'!E16 -> 0 | L16: =F16-'8 or greater'!F16-'12 or greater'!F16 -> 0
A17: 2006-2007 | B17: 0 | C17: 0 | D17: 0 | E17: 0 | F17: 1 | H17: =B17-'8 or greater'!B17-'12 or greater'!B17 -> 0 | I17: =C17-'8 or greater'!C17-'12 or greater'!C17 -> 0 | J17: =D17-'8 or greater'!D17-'12 or greater'!D17 -> 0 | K17: =E17-'8 or greater'!E17-'12 or greater'!E17 -> 0 | L17: =F17-'8 or greater'!F17-'12 or greater'!F17 -> 0
... A139: 1884-1885 | B139: 0 | C139: 0 | D139: 0 | E139: 0 | F139: 0 | H139: =B139-'8 or greater'!B139-'12 or greater'!B139 -> 0 | I139: =C139-'8 or greater'!C139-'12 or greater'!C139 -> 0 | J139: =D139-'8 or greater'!D139-'12 or greater'!D139 -> 0 | K139: =E139-'8 or greater'!E139-'12 or greater'!E139 -> 0 | L139: =F139-'8 or greater'!F139-'12 or greater'!F139 -> 0
A140: Season | B140: Nov | C140: Dec | D140: Jan | E140: Feb | F140: Mar | G140: Season | H140: Nov | I140: Dec | J140: Jan | K140: Feb | L140: Mar

Sheet 8 or greater
B1: Nov | C1: Dec | D1: Jan | E1: Feb | F1: Mar | H1: Nov | I1: Dec | J1: Jan | K1: Feb | L1: Mar | P1: Nov | Q1: count of nov | R1: Dec | S1: count of dec | T1: Jan | U1: count of jan | V1: Feb | W1: count of feb | X1: Mar | Y1: coung of march
A2: 2021-2022 | B2: 0 | C2: 1 | D2: 0 | E2: 0 | F2: 0 | H2: =B2-'12 or greater'!B2 -> 0 | I2: =C2-'12 or greater'!C2 -> 1 | J2: =D2-'12 or greater'!D2 -> 0 | K2: =E2-'12 or greater'!E2 -> 0 | L2: =F2-'12 or greater'!F2 -> 0 | P2: 0 | Q2: =COUNTIF($H$2:$H$139,P2) -> 130 | R2: 1 | S2: =COUNTIF($I$2:$I$139,R2) -> 9 | T2: 0 | U2: =COUNTIF($J$2:$J$139,T2) -> 134 | V2: 0 | W2: =COUNTIF($K$2:$K$139,V2) -> 129 | X2: 0 | Y2: =COUNTIF($L$2:$L$139,X2) -> 121
A3: 2020-2021 | B3: 0 | C3: 1 | D3: 0 | E3: 0 | F3: 0 | H3: =B3-'12 or greater'!B3 -> 0 | I3: =C3-'12 or greater'!C3 -> 1 | J3: =D3-'12 or greater'!D3 -> 0 | K3: =E3-'12 or greater'!E3 -> 0 | L3: =F3-'12 or greater'!F3 -> 0 | P3: 1 | Q3: =COUNTIF($H$2:$H$139,P3) -> 7 | R3: 0 | S3: =COUNTIF($I$2:$I$139,R3) -> 129 | T3: 1 | U3: =COUNTIF($J$2:$J$139,T3) -> 4 | V3: 1 | W3: =COUNTIF($K$2:$K$139,V3) -> 9 | X3: 1 | Y3: =COUNTIF($L$2:$L$139,X3) -> 16
A4: 2019-2020 | B4: 0 | C4: 0 | D4: 0 | E4: 0 | F4: 0 | H4: =B4-'12 or greater'!B4 -> 0 | I4: =C4-'12 or greater'!C4 -> 0 | J4: =D4-'12 or greater'!D4 -> 0 | K4: =E4-'12 or greater'!E4 -> 0 | L4: =F4-'12 or greater'!F4 -> 0 | P4: 2 | Q4: =COUNTIF($H$2:$H$139,P4) -> 1 | X4: 3 | Y4: =COUNTIF($L$2:$L$139,X4) -> 1
A5: 2018-2019 | B5: 0 | C5: 0 | D5: 0 | E5: 1 | F5: 0 | H5: =B5-'12 or greater'!B5 -> 0 | I5: =C5-'12 or greater'!C5 -> 0 | J5: =D5-'12 or greater'!D5 -> 0 | K5: =E5-'12 or greater'!E5 -> 1 | L5: =F5-'12 or greater'!F5 -> 0
A6: 2017-2018 | B6: 0 | C6: 0 | D6: 1 | E6: 0 | F6: 0 | H6: =B6-'12 or greater'!B6 -> 0 | I6: =C6-'12 or greater'!C6 -> 0 | J6: =D6-'12 or greater'!D6 -> 0 | K6: =E6-'12 or greater'!E6 -> 0 | L6: =F6-'12 or greater'!F6 -> 0
A7: 2016-2017 | B7: 0 | C7: 0 | D7: 0 | E7: 0 | F7: 0 | H7: =B7-'12 or greater'!B7 -> 0 | I7: =C7-'12 or greater'!C7 -> 0 | J7: =D7-'12 or greater'!D7 -> 0 | K7: =E7-'12 or greater'!E7 -> 0 | L7: =F7-'12 or greater'!F7 -> 0
A8: 2015-2016 | B8: 0 | C8: 0 | D8: 0 | E8: 1 | F8: 0 | H8: =B8-'12 or greater'!B8 -> 0 | I8: =C8-'12 or greater'!C8 -> 0 | J8: =D8-'12 or greater'!D8 -> 0 | K8: =E8-'12 or greater'!E8 -> 1 | L8: =F8-'12 or greater'!F8 -> 0
A9: 2014-2015 | B9: 0 | C9: 0 | D9: 0 | E9: 0 | F9: 0 | H9: =B9-'12 or greater'!B9 -> 0 | I9: =C9-'12 or greater'!C9 -> 0 | J9: =D9-'12 or greater'!D9 -> 0 | K9: =E9-'12 or greater'!E9 -> 0 | L9: =F9-'12 or greater'!F9 -> 0
A10: 2013-2014 | B10: 0 | C10: 0 | D10: 0 | E10: 1 | F10: 0 | H10: =B10-'12 or greater'!B10 -> 0 | I10: =C10-'12 or greater'!C10 -> 0 | J10: =D10-'12 or greater'!D10 -> 0 | K10: =E10-'12 or greater'!E10 -> 1 | L10: =F10-'12 or greater'!F10 -> 0
A11: 2012-2013 | B11: 0 | C11: 1 | D11: 0 | E11: 0 | F11: 0 | H11: =B11-'12 or greater'!B11 -> 0 | I11: =C11-'12 or greater'!C11 -> 1 | J11: =D11-'12 or greater'!D11 -> 0 | K11: =E11-'12 or greater'!E11 -> 0 | L11: =F11-'12 or greater'!F11 -> 0
A12: 2011-2012 | B12: 0 | C12: 0 | D12: 0 | E12: 0 | F12: 0 | H12: =B12-'12 or greater'!B12 -> 0 | I12: =C12-'12 or greater'!C12 -> 0 | J12: =D12-'12 or greater'!D12 -> 0 | K12: =E12-'12 or greater'!E12 -> 0 | L12: =F12-'12 or greater'!F12 -> 0
A13: 2010-2011 | B13: 0 | C13: 1 | D13: 0 | E13: 1 | F13: 0 | H13: =B13-'12 or greater'!B13 -> 0 | I13: =C13-'12 or greater'!C13 -> 0 | J13: =D13-'12 or greater'!D13 -> 0 | K13: =E13-'12 or greater'!E13 -> 1 | L13: =F13-'12 or greater'!F13 -> 0
A14: 2009-2010 | B14: 0 | C14: 0 | D14: 0 | E14: 0 | F14: 0 | H14: =B14-'12 or greater'!B14 -> 0 | I14: =C14-'12 or greater'!C14 -> 0 | J14: =D14-'12 or greater'!D14 -> 0 | K14: =E14-'12 or greater'!E14 -> 0 | L14: =F14-'12 or greater'!F14 -> 0
A15: 2008-2009 | B15: 0 | C15: 0 | D15: 0 | E15: 0 | F15: 0 | H15: =B15-'12 or greater'!B15 -> 0 | I15: =C15-'12 or greater'!C15 -> 0 | J15: =D15-'12 or greater'!D15 -> 0 | K15: =E15-'12 or greater'!E15 -> 0 | L15: =F15-'12 or greater'!F15 -> 0
A16: 2007-2008 | B16: 0 | C16: 0 | D16: 0 | E16: 0 | F16: 0 | H16: =B16-'12 or greater'!B16 -> 0 | I16: =C16-'12 or greater'!C16 -> 0 | J16: =D16-'12 or greater'!D16 -> 0 | K16: =E16-'12 or greater'!E16 -> 0 | L16: =F16-'12 or greater'!F16 -> 0
... A139: 1884-1885 | B139: 0 | C139: 0 | D139: 0 | E139: 0 | F139: 0 | H139: =B139-'12 or greater'!B139 -> 0 | I139: =C139-'12 or greater'!C139 -> 0 | J139: =D139-'12 or greater'!D139 -> 0 | K139: =E139-'12 or greater'!E139 -> 0 | L139: =F139-'12 or greater'!F139 -> 0

Sheet 12 or greater
B1: Nov | C1: Dec | D1: Jan | E1: Feb | F1: Mar | H1: Nov | J1: Dec | L1: Jan | N1: Feb | P1: Mar
A2: 2021-2022 | B2: 0 | C2: 0 | D2: 0 | E2: 0 | F2: 0 | H2: 0 | I2: 137 | J2: 0 | K2: 136 | L2: 0 | M2: 135 | N2: 0 | O2: 138 | P2: 0 | Q2: 135
A3: 2020-2021 | B3: 0 | C3: 0 | D3: 0 | E3: 0 | F3: 0 | H3: 2 | I3: 1 | J3: 1 | K3: 2 | L3: 1 | M3: 2 | P3: 1 | Q3: 2
A4: 2019-2020 | B4: 0 | C4: 0 | D4: 0 | E4: 0 | F4: 0 | K4: 136 | L4: 2 | M4: 1 | P4: 2 | Q4: 1
A5: 2018-2019 | B5: 0 | C5: 0 | D5: 0 | E5: 0 | F5: 0
A6: 2017-2018 | B6: 0 | C6: 0 | D6: 1 | E6: 0 | F6: 0
A7: 2016-2017 | B7: 0 | C7: 0 | D7: 0 | E7: 0 | F7: 0
A8: 2015-2016 | B8: 0 | C8: 0 | D8: 0 | E8: 0 | F8: 0
A9: 2014-2015 | B9: 0 | C9: 0 | D9: 0 | E9: 0 | F9: 0
A10: 2013-2014 | B10: 0 | C10: 0 | D10: 0 | E10: 0 | F10: 0
A11: 2012-2013 | B11: 0 | C11: 0 | D11: 0 | E11: 0 | F11: 0
A12: 2011-2012 | B12: 0 | C12: 0 | D12: 0 | E12: 0 | F12: 0
A13: 2010-2011 | B13: 0 | C13: 1 | D13: 0 | E13: 0 | F13: 0
A14: 2009-2010 | B14: 0 | C14: 0 | D14: 0 | E14: 0 | F14: 0
A15: 2008-2009 | B15: 0 | C15: 0 | D15: 0 | E15: 0 | F15: 0
A16: 2007-2008 | B16: 0 | C16: 0 | D16: 0 | E16: 0 | F16: 0
... A139: 1884-1885 | B139: 0 | C139: 0 | D139: 0 | E139: 0 | F139: 0
